Workbook

Sheet Unit EDL
A1: GCE UNIT EDL
A3: TAMCN | B3: Description | C3: Qty
A4: A0254 | B4: COC V3 | C4: 1
A5: A0255 | B5: COC V4 | C5: 5
A6: B0018 | B6: GEN/AC Trailer | C6: 1
A7: B0035 | B7: MRAP CAT III | C7: 3
A8: B0040 | B8: Tractor with bucket | C8: 4
A9: B0060 | B9: Medium Crawler Tractor | C9: 4
A10: B0063 | B10: TRAM | C10: 7
A11: B0093 | B11: HUSKY | C11: 6
A12: B0160 | B12: ABV | C12: 7
A13: B0589 | B13: M9 ACE | C13: 8
A14: B0640 | B14: Floodlight Set | C14: 6
A15: B0730 | B15: 3KW Generator | C15: 49
... A98: E1888 | B98: M1A1 | C98: 58

Sheet Loads + CPFs by TAMCN
A1: COMBAT PLANNING FACTORS TABLE
A2: TAMCN SEQUENCE
A3: POM-16
A5: WEAPON | C5: AMMUNITION | E5: GCE RATES | H5: NON-GCE RATES
A6: TAMCN | B6: NOMENCLATURE | C6: DODIC | D6: NOMENCLATURE | E6: DAILY ASSAULT | F6: DAILY SUSTAIN | G6: COMBAT LOAD | H6: DAILY ASSAULT | I6: DAILY SUSTAIN | J6: COMBAT LOAD | K6: GCE TE Qty | L6: GCE Daily Assault Rate | M6: GCE Daily Sustain Rate | O6: Assault Rate Combat Load Ratio in Days | P6: Sustain Rate Combat Load Ratio in Days
A8: B0160 | B8: Assault Breacher Vehicle | C8: A518 | D8: Cartridge, Caliber .50 4 SLAP M903/1 SLAP-T M962 Linked | E8: 0 | F8: 0 | G8: 200 | K8: =IF(ISNA(VLOOKUP($A8,'Unit EDL'!$A:$C,3,FALSE)),0,VLOOKUP($A8,'Unit EDL'!$A:$C,3,FALSE)) -> 7 | L8: =K8*E8 -> 0 | M8: =K8*F8 -> 0 | O8: =IF($K8=0,0,IF(E8=0,999,$G8/E8)) -> 999 | P8: =IF($K8=0,0,IF(F8=0,999,$G8/F8)) -> 999
A9: B0160 | C9: A576 | D9: Cartridge, Caliber .50 4 API M8/1 API-T M20 Linked | E9: 0.918 | F9: 0.779 | G9: 600 | H9: 0 | I9: 0 | J9: 600 | K9: =IF(ISNA(VLOOKUP($A9,'Unit EDL'!$A:$C,3,FALSE)),0,VLOOKUP($A9,'Unit EDL'!$A:$C,3,FALSE)) -> 7 | L9: =K9*E9 -> 6.426 | M9: =K9*F9 -> 5.453 | O9: =IF($K9=0,0,IF(E9=0,999,$G9/E9)) -> 653.59477 | P9: =IF($K9=0,0,IF(F9=0,999,$G9/F9)) -> 770.21823
A10: B0160 | C10: GG24 | D10: Grenade, Launcher Smoke Infrared Screening | E10: 2.835 | F10: 2.835 | G10: 24 | H10: 0 | I10: 0 | J10: 24 | K10: =IF(ISNA(VLOOKUP($A10,'Unit EDL'!$A:$C,3,FALSE)),0,VLOOKUP($A10,'Unit EDL'!$A:$C,3,FALSE)) -> 7 | L10: =K10*E10 -> 19.845 | M10: =K10*F10 -> 19.845 | O10: =IF($K10=0,0,IF(E10=0,999,$G10/E10)) -> 8.4656085 | P10: =IF($K10=0,0,IF(F10=0,999,$G10/F10)) -> 8.4656085
A11: B0160 | C11: J143 | D11: Rocket Motor, 5-inch MK22 Mod 4 | E11: 0.886 | F11: 0.804 | G11: 2 | H11: 0 | I11: 0 | J11: 2 | K11: =IF(ISNA(VLOOKUP($A11,'Unit EDL'!$A:$C,3,FALSE)),0,VLOOKUP($A11,'Unit EDL'!$A:$C,3,FALSE)) -> 7 | L11: =K11*E11 -> 6.202 | M11: =K11*F11 -> 5.628 | O11: =IF($K11=0,0,IF(E11=0,999,$G11/E11)) -> 2.2573363 | P11: =IF($K11=0,0,IF(F11=0,999,$G11/F11)) -> 2.4875622
A12: B0160 | C12: M913 | D12: Charge, Demolition High Explosive Linear M58A4 | E12: 0.886 | F12: 0.804 | G12: 2 | H12: 0 | I12: 0 | J12: 2 | K12: =IF(ISNA(VLOOKUP($A12,'Unit EDL'!$A:$C,3,FALSE)),0,VLOOKUP($A12,'Unit EDL'!$A:$C,3,FALSE)) -> 7 | L12: =K12*E12 -> 6.202 | M12: =K12*F12 -> 5.628 | O12: =IF($K12=0,0,IF(E12=0,999,$G12/E12)) -> 2.2573363 | P12: =IF($K12=0,0,IF(F12=0,999,$G12/F12)) -> 2.4875622
K13: =IF(ISNA(VLOOKUP($A13,'Unit EDL'!$A:$C,3,FALSE)),0,VLOOKUP($A13,'Unit EDL'!$A:$C,3,FALSE)) -> 0 | L13: =K13*E13 -> 0 | M13: =K13*F13 -> 0 | O13: =IF($K13=0,0,IF(E13=0,999,$G13/E13)) -> 0 | P13: =IF($K13=0,0,IF(F13=0,999,$G13/F13)) -> 0
A14: B0471 | B14: Demolition Equipment, Squad | C14: G900 | D14: Grenade, Hand Incendiary Thermite AN-M14 | E14: 0 | F14: 0 | G14: 6 | H14: 1.546 | I14: 0.317 | J14: 6 | K14: =IF(ISNA(VLOOKUP($A14,'Unit EDL'!$A:$C,3,FALSE)),0,VLOOKUP($A14,'Unit EDL'!$A:$C,3,FALSE)) -> 0 | L14: =K14*E14 -> 0 | M14: =K14*F14 -> 0 | O14: =IF($K14=0,0,IF(E14=0,999,$G14/E14)) -> 0 | P14: =IF($K14=0,0,IF(F14=0,999,$G14/F14)) -> 0
A15: B0471 | C15: M032 | D15: Charge, Demolition Block TNT 1-Pound | E15: 3.299 | F15: 3.299 | G15: 48 | H15: 19.008 | I15: 3.299 | J15: 48 | K15: =IF(ISNA(VLOOKUP($A15,'Unit EDL'!$A:$C,3,FALSE)),0,VLOOKUP($A15,'Unit EDL'!$A:$C,3,FALSE)) -> 0 | L15: =K15*E15 -> 0 | M15: =K15*F15 -> 0 | O15: =IF($K15=0,0,IF(E15=0,999,$G15/E15)) -> 0 | P15: =IF($K15=0,0,IF(F15=0,999,$G15/F15)) -> 0
A16: B0471 | C16: M039 | D16: Charge, Demolition Cratering 40-Pound | H16: 1.649 | I16: 0.114 | J16: 0 | K16: =IF(ISNA(VLOOKUP($A16,'Unit EDL'!$A:$C,3,FALSE)),0,VLOOKUP($A16,'Unit EDL'!$A:$C,3,FALSE)) -> 0 | L16: =K16*E16 -> 0 | M16: =K16*F16 -> 0 | O16: =IF($K16=0,0,IF(E16=0,999,$G16/E16)) -> 0 | P16: =IF($K16=0,0,IF(F16=0,999,$G16/F16)) -> 0
A17: B0471 | C17: M130 | D17: Cap, Blasting Electric M6 | E17: 9.897 | F17: 9.897 | G17: 50 | H17: 19.381 | I17: 9.897 | J17: 100 | K17: =IF(ISNA(VLOOKUP($A17,'Unit EDL'!$A:$C,3,FALSE)),0,VLOOKUP($A17,'Unit EDL'!$A:$C,3,FALSE)) -> 0 | L17: =K17*E17 -> 0 | M17: =K17*F17 -> 0 | O17: =IF($K17=0,0,IF(E17=0,999,$G17/E17)) -> 0 | P17: =IF($K17=0,0,IF(F17=0,999,$G17/F17)) -> 0
A18: B0471 | C18: M131 | D18: Cap, Blasting Non-Electric M7 | E18: 23.097 | F18: 21.028 | G18: 100 | H18: 40.585 | I18: 18.979 | J18: 50 | K18: =IF(ISNA(VLOOKUP($A18,'Unit EDL'!$A:$C,3,FALSE)),0,VLOOKUP($A18,'Unit EDL'!$A:$C,3,FALSE)) -> 0 | L18: =K18*E18 -> 0 | M18: =K18*F18 -> 0 | O18: =IF($K18=0,0,IF(E18=0,999,$G18/E18)) -> 0 | P18: =IF($K18=0,0,IF(F18=0,999,$G18/F18)) -> 0
A19: B0471 | C19: M421 | D19: Charge, Demolition Shaped M3 Series 40-Pound | H19: 1.649 | I19: 0.114 | J19: 0 | K19: =IF(ISNA(VLOOKUP($A19,'Unit EDL'!$A:$C,3,FALSE)),0,VLOOKUP($A19,'Unit EDL'!$A:$C,3,FALSE)) -> 0 | L19: =K19*E19 -> 0 | M19: =K19*F19 -> 0 | O19: =IF($K19=0,0,IF(E19=0,999,$G19/E19)) -> 0 | P19: =IF($K19=0,0,IF(F19=0,999,$G19/F19)) -> 0
A20: B0471 | C20: M456 | D20: Cord, Detonating PETN Type I Class E | E20: 68.732 | F20: 68.732 | G20: 3000 | H20: 319.818 | I20: 68.732 | J20: 1500 | K20: =IF(ISNA(VLOOKUP($A20,'Unit EDL'!$A:$C,3,FALSE)),0,VLOOKUP($A20,'Unit EDL'!$A:$C,3,FALSE)) -> 0 | L20: =K20*E20 -> 0 | M20: =K20*F20 -> 0 | O20: =IF($K20=0,0,IF(E20=0,999,$G20/E20)) -> 0 | P20: =IF($K20=0,0,IF(F20=0,999,$G20/F20)) -> 0
A21: B0471 | C21: M670 | D21: Fuse, Blasting Time M700 | E21: 159.538 | F21: 118.152 | G21: 1000 | H21: 165.214 | I21: 77.186 | J21: 500 | K21: =IF(ISNA(VLOOKUP($A21,'Unit EDL'!$A:$C,3,FALSE)),0,VLOOKUP($A21,'Unit EDL'!$A:$C,3,FALSE)) -> 0 | L21: =K21*E21 -> 0 | M21: =K21*F21 -> 0 | O21: =IF($K21=0,0,IF(E21=0,999,$G21/E21)) -> 0 | P21: =IF($K21=0,0,IF(F21=0,999,$G21/F21)) -> 0
A22: B0471 | C22: M757 | D22: Charge, Assembly Demolition M183 Comp C-4 | E22: 8.351 | F22: 5.06 | G22: 10 | H22: 7.852 | I22: 1.339 | J22: 10 | K22: =IF(ISNA(VLOOKUP($A22,'Unit EDL'!$A:$C,3,FALSE)),0,VLOOKUP($A22,'Unit EDL'!$A:$C,3,FALSE)) -> 0 | L22: =K22*E22 -> 0 | M22: =K22*F22 -> 0 | O22: =IF($K22=0,0,IF(E22=0,999,$G22/E22)) -> 0 | P22: =IF($K22=0,0,IF(F22=0,999,$G22/F22)) -> 0
A23: B0471 | C23: MN08 | D23: Igniter, Time Blasting Fuse with Shock Tube Capability M81 | E23: 16.314 | F23: 13.682 | G23: 100 | H23: 35.053 | I23: 14.715 | J23: 100 | K23: =IF(ISNA(VLOOKUP($A23,'Unit EDL'!$A:$C,3,FALSE)),0,VLOOKUP($A23,'Unit EDL'!$A:$C,3,FALSE)) -> 0 | L23: =K23*E23 -> 0 | M23: =K23*F23 -> 0 | O23: =IF($K23=0,0,IF(E23=0,999,$G23/E23)) -> 0 | P23: =IF($K23=0,0,IF(F23=0,999,$G23/F23)) -> 0
A24: B0471 | C24: MN14 | D24: Firing Device, Dual Mode MK54 | E24: 0.001 | F24: 0.001 | G24: 1 | H24: 0.001 | I24: 0.001 | J24: 1 | K24: =IF(ISNA(VLOOKUP($A24,'Unit EDL'!$A:$C,3,FALSE)),0,VLOOKUP($A24,'Unit EDL'!$A:$C,3,FALSE)) -> 0 | L24: =K24*E24 -> 0 | M24: =K24*F24 -> 0 | O24: =IF($K24=0,0,IF(E24=0,999,$G24/E24)) -> 0 | P24: =IF($K24=0,0,IF(F24=0,999,$G24/F24)) -> 0
A25: B0471 | C25: MN52 | D25: Detonator, Percussion, Non-Electric MK154 Mod 0 | E25: 2.577 | F25: 2.577 | G25: 50 | H25: 2.577 | I25: 2.577 | J25: 50 | K25: =IF(ISNA(VLOOKUP($A25,'Unit EDL'!$A:$C,3,FALSE)),0,VLOOKUP($A25,'Unit EDL'!$A:$C,3,FALSE)) -> 0 | L25: =K25*E25 -> 0 | M25: =K25*F25 -> 0 | O25: =IF($K25=0,0,IF(E25=0,999,$G25/E25)) -> 0 | P25: =IF($K25=0,0,IF(F25=0,999,$G25/F25)) -> 0
A26: B0471 | C26: MN79 | D26: Mine, Antipersonnel Obstacle Breaching System MK7 Mod 1 | E26: 1.805 | F26: 1.482 | G26: 2 | K26: =IF(ISNA(VLOOKUP($A26,'Unit EDL'!$A:$C,3,FALSE)),0,VLOOKUP($A26,'Unit EDL'!$A:$C,3,FALSE)) -> 0 | L26: =K26*E26 -> 0 | M26: =K26*F26 -> 0 | O26: =IF($K26=0,0,IF(E26=0,999,$G26/E26)) -> 0 | P26: =IF($K26=0,0,IF(F26=0,999,$G26/F26)) -> 0
K27: =IF(ISNA(VLOOKUP($A27,'Unit EDL'!$A:$C,3,FALSE)),0,VLOOKUP($A27,'Unit EDL'!$A:$C,3,FALSE)) -> 0 | L27: =K27*E27 -> 0 | M27: =K27*F27 -> 0 | O27: =IF($K27=0,0,IF(E27=0,999,$G27/E27)) -> 0 | P27: =IF($K27=0,0,IF(F27=0,999,$G27/F27)) -> 0
A28: B0472 | B28: Demolition Equipment, Individual | C28: M032 | D28: Charge, Demolition Block TNT 1-Pound | E28: 3.299 | F28: 3.299 | G28: 5 | H28: 3.814 | I28: 3.299 | J28: 5 | K28: =IF(ISNA(VLOOKUP($A28,'Unit EDL'!$A:$C,3,FALSE)),0,VLOOKUP($A28,'Unit EDL'!$A:$C,3,FALSE)) -> 0 | L28: =K28*E28 -> 0 | M28: =K28*F28 -> 0 | O28: =IF($K28=0,0,IF(E28=0,999,$G28/E28)) -> 0 | P28: =IF($K28=0,0,IF(F28=0,999,$G28/F28)) -> 0
A29: B0472 | C29: M131 | D29: Cap, Blasting Non-Electric M7 | E29: 10 | F29: 10 | G29: 10 | H29: 10 | I29: 10 | J29: 10 | K29: =IF(ISNA(VLOOKUP($A29,'Unit EDL'!$A:$C,3,FALSE)),0,VLOOKUP($A29,'Unit EDL'!$A:$C,3,FALSE)) -> 0 | L29: =K29*E29 -> 0 | M29: =K29*F29 -> 0 | O29: =IF($K29=0,0,IF(E29=0,999,$G29/E29)) -> 0 | P29: =IF($K29=0,0,IF(F29=0,999,$G29/F29)) -> 0
A30: B0472 | C30: M456 | D30: Cord, Detonating PETN Type I Class E | E30: 68.732 | F30: 68.732 | G30: 100 | H30: 50 | I30: 50 | J30: 50 | K30: =IF(ISNA(VLOOKUP($A30,'Unit EDL'!$A:$C,3,FALSE)),0,VLOOKUP($A30,'Unit EDL'!$A:$C,3,FALSE)) -> 0 | L30: =K30*E30 -> 0 | M30: =K30*F30 -> 0 | O30: =IF($K30=0,0,IF(E30=0,999,$G30/E30)) -> 0 | P30: =IF($K30=0,0,IF(F30=0,999,$G30/F30)) -> 0
A31: B0472 | C31: M670 | D31: Fuse, Blasting Time M700 | E31: 31.169 | F31: 27.495 | G31: 50 | H31: 50 | I31: 31.577 | J31: 50 | K31: =IF(ISNA(VLOOKUP($A31,'Unit EDL'!$A:$C,3,FALSE)),0,VLOOKUP($A31,'Unit EDL'!$A:$C,3,FALSE)) -> 0 | L31: =K31*E31 -> 0 | M31: =K31*F31 -> 0 | O31: =IF($K31=0,0,IF(E31=0,999,$G31/E31)) -> 0 | P31: =IF($K31=0,0,IF(F31=0,999,$G31/F31)) -> 0
A32: B0472 | C32: M757 | D32: Charge, Assembly Demolition M183 Comp C-4 | E32: 0.247 | F32: 0.04 | G32: 2 | H32: 1.047 | I32: 0.305 | J32: 2 | K32: =IF(ISNA(VLOOKUP($A32,'Unit EDL'!$A:$C,3,FALSE)),0,VLOOKUP($A32,'Unit EDL'!$A:$C,3,FALSE)) -> 0 | L32: =K32*E32 -> 0 | M32: =K32*F32 -> 0 | O32: =IF($K32=0,0,IF(E32=0,999,$G32/E32)) -> 0 | P32: =IF($K32=0,0,IF(F32=0,999,$G32/F32)) -> 0
A33: B0472 | C33: MN08 | D33: Igniter, Time Blasting Fuse with Shock Tube Capability M81 | E33: 10.536 | F33: 10.354 | G33: 20 | H33: 20 | I33: 10.56 | J33: 20 | K33: =IF(ISNA(VLOOKUP($A33,'Unit EDL'!$A:$C,3,FALSE)),0,VLOOKUP($A33,'Unit EDL'!$A:$C,3,FALSE)) -> 0 | L33: =K33*E33 -> 0 | M33: =K33*F33 -> 0 | O33: =IF($K33=0,0,IF(E33=0,999,$G33/E33)) -> 0 | P33: =IF($K33=0,0,IF(F33=0,999,$G33/F33)) -> 0
A34: B0472 | C34: MN14 | D34: Firing Device, Dual Mode MK54 | E34: 0.001 | F34: 0.001 | G34: 1 | H34: 0.001 | I34: 0.001 | J34: 1 | K34: =IF(ISNA(VLOOKUP($A34,'Unit EDL'!$A:$C,3,FALSE)),0,VLOOKUP($A34,'Unit EDL'!$A:$C,3,FALSE)) -> 0 | L34: =K34*E34 -> 0 | M34: =K34*F34 -> 0 | O34: =IF($K34=0,0,IF(E34=0,999,$G34/E34)) -> 0 | P34: =IF($K34=0,0,IF(F34=0,999,$G34/F34)) -> 0
A35: B0472 | C35: MN52 | D35: Detonator, Percussion, Non-Electric MK154 Mod 0 | E35: 2.577 | F35: 2.577 | G35: 10 | H35: 2.577 | I35: 2.577 | J35: 10 | K35: =IF(ISNA(VLOOKUP($A35,'Unit EDL'!$A:$C,3,FALSE)),0,VLOOKUP($A35,'Unit EDL'!$A:$C,3,FALSE)) -> 0 | L35: =K35*E35 -> 0 | M35: =K35*F35 -> 0 | O35: =IF($K35=0,0,IF(E35=0,999,$G35/E35)) -> 0 | P35: =IF($K35=0,0,IF(F35=0,999,$G35/F35)) -> 0
K36: =IF(ISNA(VLOOKUP($A36,'Unit EDL'!$A:$C,3,FALSE)),0,VLOOKUP($A36,'Unit EDL'!$A:$C,3,FALSE)) -> 0 | L36: =K36*E36 -> 0 | M36: =K36*F36 -> 0 | O36: =IF($K36=0,0,IF(E36=0,999,$G36/E36)) -> 0 | P36: =IF($K36=0,0,IF(F36=0,999,$G36/F36)) -> 0
A37: B0589 | B37: Armored Combat Excavator (ACE) | C37: GG24 | D37: Grenade, Launcher Smoke Infrared Screening | E37: 2.835 | F37: 2.835 | G37: 16 | H37: 0 | I37: 0 | J37: 16 | K37: =IF(ISNA(VLOOKUP($A37,'Unit EDL'!$A:$C,3,FALSE)),0,VLOOKUP($A37,'Unit EDL'!$A:$C,3,FALSE)) -> 8 | L37: =K37*E37 -> 22.68 | M37: =K37*F37 -> 22.68 | O37: =IF($K37=0,0,IF(E37=0,999,$G37/E37)) -> 5.643739 | P37: =IF($K37=0,0,IF(F37=0,999,$G37/F37)) -> 5.643739
K38: =IF(ISNA(VLOOKUP($A38,'Unit EDL'!$A:$C,3,FALSE)),0,VLOOKUP($A38,'Unit EDL'!$A:$C,3,FALSE)) -> 0 | L38: =K38*E38 -> 0 | M38: =K38*F38 -> 0 | O38: =IF($K38=0,0,IF(E38=0,999,$G38/E38)) -> 0 | P38: =IF($K38=0,0,IF(F38=0,999,$G38/F38)) -> 0
A39: B1298 | B39: Line Charge Launcher Kit | C39: J143 | D39: Rocket Motor, 5-inch MK22 Mod 4 | E39: 0.968 | F39: 0.804 | G39: 2 | H39: 0.853 | I39: 0.058 | J39: 2 | K39: =IF(ISNA(VLOOKUP($A39,'Unit EDL'!$A:$C,3,FALSE)),0,VLOOKUP($A39,'Unit EDL'!$A:$C,3,FALSE)) -> 18 | L39: =K39*E39 -> 17.424 | M39: =K39*F39 -> 14.472 | O39: =IF($K39=0,0,IF(E39=0,999,$G39/E39)) -> 2.0661157 | P39: =IF($K39=0,0,IF(F39=0,999,$G39/F39)) -> 2.4875622
A40: B1298 | C40: M913 | D40: Charge, Demolition High Explosive Linear M58A4 | E40: 0.968 | F40: 0.804 | G40: 2 | H40: 0.853 | I40: 0.058 | J40: 2 | K40: =IF(ISNA(VLOOKUP($A40,'Unit EDL'!$A:$C,3,FALSE)),0,VLOOKUP($A40,'Unit EDL'!$A:$C,3,FALSE)) -> 18 | L40: =K40*E40 -> 17.424 | M40: =K40*F40 -> 14.472 | O40: =IF($K40=0,0,IF(E40=0,999,$G40/E40)) -> 2.0661157 | P40: =IF($K40=0,0,IF(F40=0,999,$G40/F40)) -> 2.4875622
K41: =IF(ISNA(VLOOKUP($A41,'Unit EDL'!$A:$C,3,FALSE)),0,VLOOKUP($A41,'Unit EDL'!$A:$C,3,FALSE)) -> 0 | L41: =K41*E41 -> 0 | M41: =K41*F41 -> 0 | O41: =IF($K41=0,0,IF(E41=0,999,$G41/E41)) -> 0 | P41: =IF($K41=0,0,IF(F41=0,999,$G41/F41)) -> 0
A42: B1315 | B42: Mine Clear Launcher | C42: J143 | D42: Rocket Motor, 5-inch MK22 Mod 4 | E42: 2.598 | F42: 0.098 | G42: 3 | H42: 0 | I42: 0 | J42: 3 | K42: =IF(ISNA(VLOOKUP($A42,'Unit EDL'!$A:$C,3,FALSE)),0,VLOOKUP($A42,'Unit EDL'!$A:$C,3,FALSE)) -> 0 | L42: =K42*E42 -> 0 | M42: =K42*F42 -> 0 | O42: =IF($K42=0,0,IF(E42=0,999,$G42/E42)) -> 0 | P42: =IF($K42=0,0,IF(F42=0,999,$G42/F42)) -> 0
...

Sheet Ammo Pallet Calculator
A1: DODIC | C1: Units per pack | D1: Unit price | E1: Pack length | F1: Pack width | G1: Pack height | H1: Pack weight | I1: Weight per unit | J1: COMP GRP | K1: UN # | L1: NEW | S1: ASSAULT RATE | Z1: Transportation LIFT Capabilities By Type | AE1: ASSAULT RATE
M2: Pallet Data | AE2: SUSTAIN RATE
M3: Length | N3: Width | O3: Height | P3: Weight | Q3: Containers Per Pallet | S3: GCE 1 DOA ASSAULT RATE | T3: GCE 1 DOA SUSTAIN RATE | U3: Total DOA's | V3: # BOXES | W3: # PALLETS | X3: WEIGHT | Y3: NEW | Z3: VEHICLE TYPE | AA3: STANDARD PALLET CAPACITY | AB3: MAX PAYLOAD | AC3: # VEHICLES RQD BY PALLET | AD3: # VEHICLES RQD BY WEIGHT
A4: A011 | C4: 240 | D4: 0.36 | E4: 14.44 | F4: 12.53 | G4: 8.12 | H4: 39.2 | I4: =(H4/C4) -> 0.16333333 | J4: 1.4S | K4: 0012 | L4: 0.0038 | M4: 43.31 | N4: 50.12 | O4: 38 | P4: 2009 | Q4: 48 | S4: =IF($S$1="ASSAULT RATE",SUMIF('Loads + CPFs by TAMCN'!$C$8:$C$1000,'Ammo Pallet Calculator'!A4,'Loads + CPFs by TAMCN'!$L$8:$L$1000),0) -> 1786.08 | T4: =IF($S$1="SUSTAIN RATE",SUMIF('Loads + CPFs by TAMCN'!$C$8:$C$1000,'Ammo Pallet Calculator'!A4,'Loads + CPFs by TAMCN'!$M$8:$M$1000),0) -> 0 | U4: =SUM(S4:T4) -> 1786.08 | V4: =SUM(U4/C4) -> 7.442 | W4: =(V4/Q4) -> 0.15504167 | X4: =SUM(V4*H4) -> 291.7264 | Y4: =U4*L4 -> 6.787104 | Z4: 7-Ton MTVR Standard Pallets Per | AA4: 6 | AB4: 24400 | AC4: =($AA$20/AA4) -> 21.88525 | AD4: =($Z$17/AB4) -> 20.915604
A5: A014 | C5: 240 | D5: 0.25 | E5: 14.44 | F5: 12.53 | G5: 8.12 | H5: 39.2 | I5: =(H5/C5) -> 0.16333333 | J5: 1.4S | K5: 0012 | L5: 0.00283 | M5: 43.31 | N5: 50.12 | O5: 38 | P5: 2009 | Q5: 48 | S5: =IF($S$1="ASSAULT RATE",SUMIF('Loads + CPFs by TAMCN'!$C$8:$C$1000,'Ammo Pallet Calculator'!A5,'Loads + CPFs by TAMCN'!$L$8:$L$1000),0) -> 0 | T5: =IF($S$1="SUSTAIN RATE",SUMIF('Loads + CPFs by TAMCN'!$C$8:$C$1000,'Ammo Pallet Calculator'!A5,'Loads + CPFs by TAMCN'!$M$8:$M$1000),0) -> 0 | U5: =SUM(S5:T5) -> 0 | V5: =SUM(U5/C5) -> 0 | W5: =(V5/Q5) -> 0 | X5: =SUM(V5*H5) -> 0 | Y5: =U5*L5 -> 0 | Z5: 7-Ton MTVR XLB Standard Pallets Per | AA5: 8 | AB5: 30000 | AC5: =($AA$20/AA5) -> 16.413937 | AD5: =($Z$17/AB5) -> 17.011358
A6: A023 | C6: 240 | D6: 0.58 | E6: 14.44 | F6: 12.53 | G6: 8.12 | H6: 45.9 | I6: =(H6/C6) -> 0.19125 | J6: 1.4S | K6: 0012 | L6: 0.0055 | M6: 43.31 | N6: 50.12 | O6: 38 | P6: 2278 | Q6: 48 | S6: =IF($S$1="ASSAULT RATE",SUMIF('Loads + CPFs by TAMCN'!$C$8:$C$1000,'Ammo Pallet Calculator'!A6,'Loads + CPFs by TAMCN'!$L$8:$L$1000),0) -> 0 | T6: =IF($S$1="SUSTAIN RATE",SUMIF('Loads + CPFs by TAMCN'!$C$8:$C$1000,'Ammo Pallet Calculator'!A6,'Loads + CPFs by TAMCN'!$M$8:$M$1000),0) -> 0 | U6: =SUM(S6:T6) -> 0 | V6: =SUM(U6/C6) -> 0 | W6: =(V6/Q6) -> 0 | X6: =SUM(V6*H6) -> 0 | Y6: =U6*L6 -> 0 | Z6: LVS Standard Pallets Per | AA6: 8 | AB6: 45000 | AC6: =($AA$20/AA6) -> 16.413937 | AD6: =($Z$17/AB6) -> 11.340905
A7: A024 | C7: 320 | D7: 2.29 | E7: 14.44 | F7: 12.53 | G7: 8.12 | H7: 49 | I7: =(H7/C7) -> 0.153125 | J7: 1.4S | K7: 0012 | L7: 0.0031 | M7: 43.31 | N7: 50.12 | O7: 38 | P7: 2427 | Q7: 48 | S7: =IF($S$1="ASSAULT RATE",SUMIF('Loads + CPFs by TAMCN'!$C$8:$C$1000,'Ammo Pallet Calculator'!A7,'Loads + CPFs by TAMCN'!$L$8:$L$1000),0) -> 0 | T7: =IF($S$1="SUSTAIN RATE",SUMIF('Loads + CPFs by TAMCN'!$C$8:$C$1000,'Ammo Pallet Calculator'!A7,'Loads + CPFs by TAMCN'!$M$8:$M$1000),0) -> 0 | U7: =SUM(S7:T7) -> 0 | V7: =SUM(U7/C7) -> 0 | W7: =(V7/Q7) -> 0 | X7: =SUM(V7*H7) -> 0 | Y7: =U7*L7 -> 0 | Z7: Tractor Trailor Standard Pallets Per | AA7: 16 | AB7: 50000 | AC7: =($AA$20/AA7) -> 8.2069687 | AD7: =($Z$17/AB7) -> 10.206815
A8: A059 | C8: 1680 | D8: 0.56 | E8: 14.44 | F8: 12.53 | G8: 8.12 | H8: 67 | I8: =(H8/C8) -> 0.039880952 | J8: 1.4S | K8: 0012 | L8: 0.00379 | M8: 43.31 | N8: 50.12 | O8: 38 | P8: 3310 | Q8: 48 | S8: =IF($S$1="ASSAULT RATE",SUMIF('Loads + CPFs by TAMCN'!$C$8:$C$1000,'Ammo Pallet Calculator'!A8,'Loads + CPFs by TAMCN'!$L$8:$L$1000),0) -> 164144.3 | T8: =IF($S$1="SUSTAIN RATE",SUMIF('Loads + CPFs by TAMCN'!$C$8:$C$1000,'Ammo Pallet Calculator'!A8,'Loads + CPFs by TAMCN'!$M$8:$M$1000),0) -> 0 | U8: =SUM(S8:T8) -> 164144.3 | V8: =(U8/C8) -> 97.704942 | W8: =(V8/Q8) -> 2.0355196 | X8: 0 | Y8: =U8*L8 -> 622.1069 | Z8: CH-53 External Load Standard Pallet Per | AA8: 4 | AB8: 10000 | AC8: =($AA$20/AA8) -> 32.827875 | AD8: =($Z$17/AB8) -> 51.034074
A9: A063 | C9: 1640 | D9: 0.6 | E9: 14.44 | F9: 12.53 | G9: 8.12 | H9: 66.7 | I9: =(H9/C9) -> 0.040670732 | J9: 1.4S | K9: 0012 | L9: 0.00356 | M9: 43.31 | N9: 50.12 | O9: 38 | P9: 3310 | Q9: 48 | S9: =IF($S$1="ASSAULT RATE",SUMIF('Loads + CPFs by TAMCN'!$C$8:$C$1000,'Ammo Pallet Calculator'!A9,'Loads + CPFs by TAMCN'!$L$8:$L$1000),0) -> 20937.829 | T9: =IF($S$1="SUSTAIN RATE",SUMIF('Loads + CPFs by TAMCN'!$C$8:$C$1000,'Ammo Pallet Calculator'!A9,'Loads + CPFs by TAMCN'!$M$8:$M$1000),0) -> 0 | U9: =SUM(S9:T9) -> 20937.829 | V9: =(U9/C9) -> 12.766969 | W9: =(V9/Q9) -> 0.26597852 | X9: =(V9*H9) -> 851.55683 | Y9: =U9*L9 -> 74.538671 | Z9: 8x8x20 ISO Container Pallets Per | AA9: 16 | AB9: 44800 | AC9: =($AA$20/AA9) -> 8.2069687 | AD9: =($Z$17/AB9) -> 11.391534
A10: A064 | C10: 1600 | D10: 0.63 | E10: 17 | F10: 13.38 | G10: 9.38 | H10: 75 | I10: =(H10/C10) -> 0.046875 | J10: 1.4S | K10: 0012 | L10: 0.0044 | M10: 40.12 | N10: 51 | O10: 43 | P10: 2682 | Q10: 36 | S10: =IF($S$1="ASSAULT RATE",SUMIF('Loads + CPFs by TAMCN'!$C$8:$C$1000,'Ammo Pallet Calculator'!A10,'Loads + CPFs by TAMCN'!$L$8:$L$1000),0) -> 78492.715 | T10: =IF($S$1="SUSTAIN RATE",SUMIF('Loads + CPFs by TAMCN'!$C$8:$C$1000,'Ammo Pallet Calculator'!A10,'Loads + CPFs by TAMCN'!$M$8:$M$1000),0) -> 0 | U10: =SUM(S10:T10) -> 78492.715 | V10: =SUM(U10/C10) -> 49.057947 | W10: =(V10/Q10) -> 1.3627207 | X10: 0 | Y10: =U10*L10 -> 345.36795 | Z10: 463L Standard Pallets Per | AA10: 4 | AB10: 10000 | AC10: =($AA$20/AA10) -> 32.827875 | AD10: =($Z$17/AB10) -> 51.034074
A11: A131 | C11: 800 | D11: 0.73 | E11: 17.38 | F11: 11.5 | G11: 8.12 | H11: 77.8 | I11: =(H11/C11) -> 0.09725 | J11: 1.4S | K11: 0012 | L11: 0.0067 | M11: 35 | N11: 46 | O11: 46.12 | P11: 3152 | Q11: 40 | S11: =IF($S$1="ASSAULT RATE",SUMIF('Loads + CPFs by TAMCN'!$C$8:$C$1000,'Ammo Pallet Calculator'!A11,'Loads + CPFs by TAMCN'!$L$8:$L$1000),0) -> 145557.59 | T11: =IF($S$1="SUSTAIN RATE",SUMIF('Loads + CPFs by TAMCN'!$C$8:$C$1000,'Ammo Pallet Calculator'!A11,'Loads + CPFs by TAMCN'!$M$8:$M$1000),0) -> 0 | U11: =SUM(S11:T11) -> 145557.59 | V11: =SUM(U11/C11) -> 181.94699 | W11: =(V11/Q11) -> 4.5486747 | X11: =SUM(V11*H11) -> 14155.476 | Y11: =U11*L11 -> 975.23586 | Z11: C-130 Plane Standard Pallets Per (6 463L's Per) | AA11: 24 | AB11: 24000 | AC11: =($AA$20/AA11) -> 5.4713124 | AD11: =($Z$17/AB11) -> 21.264198
A12: A260 | C12: 2000 | D12: 0.13 | E12: 14.44 | F12: 12.53 | G12: 8.5 | H12: 82.3 | I12: =(H12/C12) -> 0.04115 | J12: 1.4S | K12: 0012 | L12: 0.0007 | M12: 43.31 | N12: 50.12 | O12: 38 | P12: 4025 | Q12: 48 | S12: =IF($S$1="ASSAULT RATE",SUMIF('Loads + CPFs by TAMCN'!$C$8:$C$1000,'Ammo Pallet Calculator'!A12,'Loads + CPFs by TAMCN'!$L$8:$L$1000),0) -> 0 | T12: =IF($S$1="SUSTAIN RATE",SUMIF('Loads + CPFs by TAMCN'!$C$8:$C$1000,'Ammo Pallet Calculator'!A12,'Loads + CPFs by TAMCN'!$M$8:$M$1000),0) -> 0 | U12: =SUM(S12:T12) -> 0 | V12: =SUM(U12/C12) -> 0 | W12: =(V12/Q12) -> 0 | X12: =SUM(V12*H12) -> 0 | Y12: =U12*L12 -> 0 | Z12: C-141 Plane Standard Pallets Per (13 463L's Per) | AA12: 52 | AB12: 38000 | AC12: =($AA$20/AA12) -> 2.5252211 | AD12: =($Z$17/AB12) -> 13.43002
A13: A363 | C13: 2000 | D13: 0.13 | E13: 14.44 | F13: 12.53 | G13: 8.5 | H13: 79.7 | I13: =(H13/C13) -> 0.03985 | J13: 1.4S | K13: 0012 | L13: 0.000911 | M13: 43.31 | N13: 50.12 | O13: 38 | P13: 3934 | Q13: 48 | S13: =IF($S$1="ASSAULT RATE",SUMIF('Loads + CPFs by TAMCN'!$C$8:$C$1000,'Ammo Pallet Calculator'!A13,'Loads + CPFs by TAMCN'!$L$8:$L$1000),0) -> 3034.56 | T13: =IF($S$1="SUSTAIN RATE",SUMIF('Loads + CPFs by TAMCN'!$C$8:$C$1000,'Ammo Pallet Calculator'!A13,'Loads + CPFs by TAMCN'!$M$8:$M$1000),0) -> 0 | U13: =SUM(S13:T13) -> 3034.56 | V13: =SUM(U13/C13) -> 1.51728 | W13: =(V13/Q13) -> 0.03161 | X13: =SUM(V13*H13) -> 120.92722 | Y13: =U13*L13 -> 2.7644842 | Z13: C-5 Plane Standard Pallets Per (36 463L's Per) | AA13: 144 | AB13: 120000 | AC13: =($AA$20/AA13) -> 0.91188541 | AD13: =($Z$17/AB13) -> 4.2528395
A14: A475 | C14: 2000 | D14: 0.21 | E14: 14.44 | F14: 12.53 | G14: 8.5 | H14: 107 | I14: =(H14/C14) -> 0.0535 | J14: 1.4S | K14: 0012 | L14: 0.0008 | M14: 43.31 | N14: 50.12 | O14: 29.88 | P14: 3977 | Q14: 36 | S14: =IF($S$1="ASSAULT RATE",SUMIF('Loads + CPFs by TAMCN'!$C$8:$C$1000,'Ammo Pallet Calculator'!A14,'Loads + CPFs by TAMCN'!$L$8:$L$1000),0) -> 0 | T14: =IF($S$1="SUSTAIN RATE",SUMIF('Loads + CPFs by TAMCN'!$C$8:$C$1000,'Ammo Pallet Calculator'!A14,'Loads + CPFs by TAMCN'!$M$8:$M$1000),0) -> 0 | U14: =SUM(S14:T14) -> 0 | V14: =SUM(U14/C14) -> 0 | W14: =(V14/Q14) -> 0 | X14: =SUM(V14*H14) -> 0 | Y14: =U14*L14 -> 0 | Z14: C-17 Plane Standard Pallets Per (18 463L's Per) | AA14: 72 | AB14: 90000 | AC14: =($AA$20/AA14) -> 1.8237708 | AD14: =($Z$17/AB14) -> 5.6704527
A15: A518 | C15: 200 | D15: 8.63 | E15: 14.44 | F15: 12.53 | G15: 8.5 | H15: 77 | I15: =(H15/C15) -> 0.385 | J15: 1.4C | K15: 0339 | L15: 0.04201 | M15: 43.31 | N15: 50.12 | O15: 38 | P15: 3771 | Q15: 48 | S15: =IF($S$1="ASSAULT RATE",SUMIF('Loads + CPFs by TAMCN'!$C$8:$C$1000,'Ammo Pallet Calculator'!A15,'Loads + CPFs by TAMCN'!$L$8:$L$1000),0) -> 328.348 | T15: =IF($S$1="SUSTAIN RATE",SUMIF('Loads + CPFs by TAMCN'!$C$8:$C$1000,'Ammo Pallet Calculator'!A15,'Loads + CPFs by TAMCN'!$M$8:$M$1000),0) -> 0 | U15: =SUM(S15:T15) -> 328.348 | V15: =SUM(U15/C15) -> 1.64174 | W15: =(V15/Q15) -> 0.034202917 | X15: =SUM(V15*H15) -> 126.41398 | Y15: =U15*L15 -> 13.793899
A16: A576 | C16: 200 | D16: 3.29 | E16: 14.44 | F16: 12.53 | G16: 8.5 | H16: 77.1 | I16: =(H16/C16) -> 0.3855 | J16: 1.4C | K16: 0300 | L16: 0.0336 | M16: 43.31 | N16: 50.12 | O16: 38 | P16: 3691 | Q16: 48 | S16: =IF($S$1="ASSAULT RATE",SUMIF('Loads + CPFs by TAMCN'!$C$8:$C$1000,'Ammo Pallet Calculator'!A16,'Loads + CPFs by TAMCN'!$L$8:$L$1000),0) -> 106965.16 | T16: =IF($S$1="SUSTAIN RATE",SUMIF('Loads + CPFs by TAMCN'!$C$8:$C$1000,'Ammo Pallet Calculator'!A16,'Loads + CPFs by TAMCN'!$M$8:$M$1000),0) -> 0 | U16: =SUM(S16:T16) -> 106965.16 | V16: =SUM(U16/C16) -> 534.82579 | W16: =(V16/Q16) -> 11.142204 | X16: =SUM(V16*H16) -> 41235.068 | Y16: =U16*L16 -> 3594.0293 | Z16: TOTAL WT | AA16: TOTAL NEW
A17: A606 | C17: 240 | D17: 8.76 | E17: 14.44 | F17: 12.53 | G17: 8.5 | H17: 79 | I17: =(H17/C17) -> 0.32916667 | J17: 1.4G | K17: 0300 | L17: 0.0394 | M17: 43.31 | N17: 50.12 | O17: 38 | P17: 3867 | Q17: 48 | S17: =IF($S$1="ASSAULT RATE",SUMIF('Loads + CPFs by TAMCN'!$C$8:$C$1000,'Ammo Pallet Calculator'!A17,'Loads + CPFs by TAMCN'!$L$8:$L$1000),0) -> 287.945 | T17: =IF($S$1="SUSTAIN RATE",SUMIF('Loads + CPFs by TAMCN'!$C$8:$C$1000,'Ammo Pallet Calculator'!A17,'Loads + CPFs by TAMCN'!$M$8:$M$1000),0) -> 0 | U17: =SUM(S17:T17) -> 287.945 | V17: =SUM(U17/C17) -> 1.1997708 | W17: =(V17/Q17) -> 0.024995226 | X17: =SUM(V17*H17) -> 94.781896 | Y17: =U17*L17 -> 11.345033 | Z17: =SUM(X4:X174) -> 510340.74 | AA17: =SUM(Y4:Y174) -> 77622.329
A18: A974 | C18: 55 | D18: 26.56 | E18: 18.62 | F18: 10.62 | G18: 14.62 | H18: 98.5 | I18: =(H18/C18) -> 1.7909091 | J18: 1.4C | K18: 0339 | L18: 0.21661 | M18: 44.75 | N18: 53.12 | O18: 34.75 | P18: 2139 | Q18: 20 | S18: =IF($S$1="ASSAULT RATE",SUMIF('Loads + CPFs by TAMCN'!$C$8:$C$1000,'Ammo Pallet Calculator'!A18,'Loads + CPFs by TAMCN'!$L$8:$L$1000),0) -> 356.972 | T18: =IF($S$1="SUSTAIN RATE",SUMIF('Loads + CPFs by TAMCN'!$C$8:$C$1000,'Ammo Pallet Calculator'!A18,'Loads + CPFs by TAMCN'!$M$8:$M$1000),0) -> 0 | U18: =SUM(S18:T18) -> 356.972 | V18: =SUM(U18/C18) -> 6.4904 | W18: =(V18/Q18) -> 0.32452 | X18: =SUM(V18*H18) -> 639.3044 | Y18: =U18*L18 -> 77.323705
A19: A975 | C19: 55 | D19: 35.56 | E19: 18.62 | F19: 10.62 | G19: 14.62 | H19: 98.5 | I19: =(H19/C19) -> 1.7909091 | J19: 1.2E(02) | K19: 0321 | L19: 0.268985 | M19: 44.75 | N19: 53.12 | O19: 34.75 | P19: 2139 | Q19: 20 | S19: =IF($S$1="ASSAULT RATE",SUMIF('Loads + CPFs by TAMCN'!$C$8:$C$1000,'Ammo Pallet Calculator'!A19,'Loads + CPFs by TAMCN'!$L$8:$L$1000),0) -> 1154.3 | T19: =IF($S$1="SUSTAIN RATE",SUMIF('Loads + CPFs by TAMCN'!$C$8:$C$1000,'Ammo Pallet Calculator'!A19,'Loads + CPFs by TAMCN'!$M$8:$M$1000),0) -> 0 | U19: =SUM(S19:T19) -> 1154.3 | V19: =SUM(U19/C19) -> 20.987273 | W19: =(V19/Q19) -> 1.0493636 | X19: =SUM(V19*H19) -> 2067.2464 | Y19: =U19*L19 -> 310.48939 | Z19: TOTL SHT TONS | AA19: TOTAL PALLETS
A20: AA11 | C20: 920 | D20: 0.7 | E20: 14.44 | F20: 12.53 | G20: 8.5 | H20: 73.5 | I20: =(H20/C20) -> 0.079891304 | J20: 1.4S | K20: 0012 | L20: 0.0067 | M20: 43.31 | N20: 50.12 | O20: 38 | P20: 3603 | Q20: 48 | S20: =IF($S$1="ASSAULT RATE",SUMIF('Loads + CPFs by TAMCN'!$C$8:$C$1000,'Ammo Pallet Calculator'!A20,'Loads + CPFs by TAMCN'!$L$8:$L$1000),0) -> 308.256 | T20: =IF($S$1="SUSTAIN RATE",SUMIF('Loads + CPFs by TAMCN'!$C$8:$C$1000,'Ammo Pallet Calculator'!A20,'Loads + CPFs by TAMCN'!$M$8:$M$1000),0) -> 0 | U20: =SUM(S20:T20) -> 308.256 | V20: =SUM(U20/C20) -> 0.33506087 | W20: =(V20/Q20) -> 0.0069804348 | X20: =SUM(V20*H20) -> 24.626974 | Y20: =U20*L20 -> 2.0653152 | Z20: =Z17/2000 -> 255.17037 | AA20: =SUM(W4:W174) -> 131.3115
A21: A136 | C21: 920 | D21: 0.7 | E21: 14.44 | F21: 12.53 | G21: 8.5 | H21: 73.5 | I21: =(H21/C21) -> 0.079891304 | J21: 1.4S | K21: 0012 | L21: 0.0067 | M21: 43.31 | N21: 50.12 | O21: 38 | P21: 3603 | Q21: 48 | S21: =IF($S$1="ASSAULT RATE",SUMIF('Loads + CPFs by TAMCN'!$C$8:$C$1000,'Ammo Pallet Calculator'!A21,'Loads + CPFs by TAMCN'!$L$8:$L$1000),0) -> 0 | T21: =IF($S$1="SUSTAIN RATE",SUMIF('Loads + CPFs by TAMCN'!$C$8:$C$1000,'Ammo Pallet Calculator'!A21,'Loads + CPFs by TAMCN'!$M$8:$M$1000),0) -> 0 | U21: =SUM(S21:T21) -> 0 | V21: =SUM(U21/C21) -> 0 | W21: =(V21/Q21) -> 0 | X21: =SUM(V21*H21) -> 0 | Y21: =U21*L21 -> 0
A22: A986 | C22: 42 | E22: 44.81 | F22: 40.75 | G22: 33.62 | H22: 2465 | I22: =(H22/C22) -> 58.690476 | J22: 1.2C | K22: 0328 | L22: 0.2141 | M22: 44.81 | N22: 40.75 | O22: 33.62 | P22: 2465 | Q22: 42 | S22: =IF($S$1="ASSAULT RATE",SUMIF('Loads + CPFs by TAMCN'!$C$8:$C$1000,'Ammo Pallet Calculator'!A22,'Loads + CPFs by TAMCN'!$L$8:$L$1000),0) -> 152.992 | T22: =IF($S$1="SUSTAIN RATE",SUMIF('Loads + CPFs by TAMCN'!$C$8:$C$1000,'Ammo Pallet Calculator'!A22,'Loads + CPFs by TAMCN'!$M$8:$M$1000),0) -> 0 | U22: =SUM(S22:T22) -> 152.992 | V22: =SUM(U22/C22) -> 3.6426667 | W22: =(V22/Q22) -> 0.086730159 | X22: =SUM(V22*H22) -> 8979.1733 | Y22: =U22*L22 -> 32.755587
A23: AA29 | C23: 320 | D23: 3.75 | E23: 14.44 | F23: 12.53 | G23: 8.12 | H23: 55.5 | I23: =(H23/C23) -> 0.1734375 | J23: 1.4S | K23: 0012 | L23: 0.00061 | M23: 43.31 | N23: 50.12 | O23: 38 | P23: 2739 | Q23: 48 | S23: =IF($S$1="ASSAULT RATE",SUMIF('Loads + CPFs by TAMCN'!$C$8:$C$1000,'Ammo Pallet Calculator'!A23,'Loads + CPFs by TAMCN'!$L$8:$L$1000),0) -> 0 | T23: =IF($S$1="SUSTAIN RATE",SUMIF('Loads + CPFs by TAMCN'!$C$8:$C$1000,'Ammo Pallet Calculator'!A23,'Loads + CPFs by TAMCN'!$M$8:$M$1000),0) -> 0 | U23: =SUM(S23:T23) -> 0 | V23: =SUM(U23/C23) -> 0 | W23: =(V23/Q23) -> 0 | X23: =SUM(V23*H23) -> 0 | Y23: =U23*L23 -> 0
A24: AA03 | C24: 960 | E24: 17.38 | F24: 11.5 | G24: 8.12 | H24: 79.8 | I24: =(H24/C24) -> 0.083125 | J24: 1.4C | K24: 0339 | L24: 0.006449 | M24: 46 | N24: 35 | O24: 46.13 | P24: 3033 | Q24: 40 | S24: =IF($S$1="ASSAULT RATE",SUMIF('Loads + CPFs by TAMCN'!$C$8:$C$1000,'Ammo Pallet Calculator'!A24,'Loads + CPFs by TAMCN'!$L$8:$L$1000),0) -> 1116.288 | T24: =IF($S$1="SUSTAIN RATE",SUMIF('Loads + CPFs by TAMCN'!$C$8:$C$1000,'Ammo Pallet Calculator'!A24,'Loads + CPFs by TAMCN'!$M$8:$M$1000),0) -> 0 | U24: =SUM(S24:T24) -> 1116.288 | V24: =SUM(U24/C24) -> 1.1628 | W24: =(V24/Q24) -> 0.02907 | X24: =SUM(V24*H24) -> 92.79144 | Y24: =U24*L24 -> 7.1989413
A25: AA04 | C25: 800 | E25: 17.8 | F25: 11.5 | G25: 8.12 | H25: 79.66 | I25: =(H25/C25) -> 0.099575 | J25: 1.4C | K25: 0339 | L25: 0.007874 | M25: 46 | N25: 35 | O25: 46.13 | P25: 3113 | Q25: 40 | S25: =IF($S$1="ASSAULT RATE",SUMIF('Loads + CPFs by TAMCN'!$C$8:$C$1000,'Ammo Pallet Calculator'!A25,'Loads + CPFs by TAMCN'!$L$8:$L$1000),0) -> 9966.01 | T25: =IF($S$1="SUSTAIN RATE",SUMIF('Loads + CPFs by TAMCN'!$C$8:$C$1000,'Ammo Pallet Calculator'!A25,'Loads + CPFs by TAMCN'!$M$8:$M$1000),0) -> 0 | U25: =SUM(S25:T25) -> 9966.01 | V25: =SUM(U25/C25) -> 12.457512 | W25: =(V25/Q25) -> 0.31143781 | X25: =SUM(V25*H25) -> 992.36545 | Y25: =U25*L25 -> 78.472363
A26: AA30 | C26: 320 | D26: 3.47 | E26: 14.5 | F26: 12.75 | G26: 8.38 | H26: 29.9 | I26: =(H26/C26) -> 0.0934375 | J26: 1.4S | K26: 0014 | L26: 0.00226 | M26: 43.31 | N26: 50.12 | O26: 38 | P26: 1510 | Q26: 48 | S26: =IF($S$1="ASSAULT RATE",SUMIF('Loads + CPFs by TAMCN'!$C$8:$C$1000,'Ammo Pallet Calculator'!A26,'Loads + CPFs by TAMCN'!$L$8:$L$1000),0) -> 0 | T26: =IF($S$1="SUSTAIN RATE",SUMIF('Loads + CPFs by TAMCN'!$C$8:$C$1000,'Ammo Pallet Calculator'!A26,'Loads + CPFs by TAMCN'!$M$8:$M$1000),0) -> 0 | U26: =SUM(S26:T26) -> 0 | V26: =SUM(U26/C26) -> 0 | W26: =(V26/Q26) -> 0 | X26: =SUM(V26*H26) -> 0 | Y26: =U26*L26 -> 0
A27: AA31 | C27: 320 | D27: 4.16 | E27: 14.5 | F27: 12.75 | G27: 8.38 | H27: 26.7 | I27: =(H27/C27) -> 0.0834375 | J27: 1.4S | K27: 0012 | L27: 0.00082 | M27: 43.31 | N27: 50.12 | O27: 38 | P27: 1357 | Q27: 48 | S27: =IF($S$1="ASSAULT RATE",SUMIF('Loads + CPFs by TAMCN'!$C$8:$C$1000,'Ammo Pallet Calculator'!A27,'Loads + CPFs by TAMCN'!$L$8:$L$1000),0) -> 0 | T27: =IF($S$1="SUSTAIN RATE",SUMIF('Loads + CPFs by TAMCN'!$C$8:$C$1000,'Ammo Pallet Calculator'!A27,'Loads + CPFs by TAMCN'!$M$8:$M$1000),0) -> 0 | U27: =SUM(S27:T27) -> 0 | V27: =SUM(U27/C27) -> 0 | W27: =(V27/Q27) -> 0 | X27: =SUM(V27*H27) -> 0 | Y27: =U27*L27 -> 0
A28: AA53 | C28: 500 | E28: 22.25 | F28: 9.25 | G28: 8.31 | H28: 16.2 | I28: =(H28/C28) -> 0.0324 | J28: 1.4S | K28: 0012 | L28: 0.00362 | M28: 46 | N28: 35 | O28: 46.13 | P28: 3033 | Q28: 40 | S28: =IF($S$1="ASSAULT RATE",SUMIF('Loads + CPFs by TAMCN'!$C$8:$C$1000,'Ammo Pallet Calculator'!A28,'Loads + CPFs by TAMCN'!$L$8:$L$1000),0) -> 1291.758 | T28: =IF($S$1="SUSTAIN RATE",SUMIF('Loads + CPFs by TAMCN'!$C$8:$C$1000,'Ammo Pallet Calculator'!A28,'Loads + CPFs by TAMCN'!$M$8:$M$1000),0) -> 0 | U28: =SUM(S28:T28) -> 1291.758 | V28: =SUM(U28/C28) -> 2.583516 | W28: =(V28/Q28) -> 0.0645879 | X28: =SUM(V28*H28) -> 41.852959 | Y28: =U28*L28 -> 4.676164
A29: AA54 | C29: 320 | E29: 14.44 | F29: 12.53 | G29: 10.25 | H29: 53 | I29: =(H29/C29) -> 0.165625 | J29: 1.4S | K29: 0012 | L29: 0.00341 | M29: 51 | N29: 43.5 | O29: 39 | P29: 2730 | Q29: 48 | S29: =IF($S$1="ASSAULT RATE",SUMIF('Loads + CPFs by TAMCN'!$C$8:$C$1000,'Ammo Pallet Calculator'!A29,'Loads + CPFs by TAMCN'!$L$8:$L$1000),0) -> 570 | T29: =IF($S$1="SUSTAIN RATE",SUMIF('Loads + CPFs by TAMCN'!$C$8:$C$1000,'Ammo Pallet Calculator'!A29,'Loads + CPFs by TAMCN'!$M$8:$M$1000),0) -> 0 | U29: =SUM(S29:T29) -> 570 | V29: =SUM(U29/C29) -> 1.78125 | W29: =(V29/Q29) -> 0.037109375 | X29: =SUM(V29*H29) -> 94.40625 | Y29: =U29*L29 -> 1.9437
A30: AA60 | C30: 240 | E30: 14.44 | F30: 12.53 | G30: 8.13 | H30: 56.94 | I30: =(H30/C30) -> 0.23725 | J30: 1.4S | K30: 0012 | L30: 0.00527 | M30: 51 | N30: 43.5 | O30: 39 | P30: 2834 | Q30: 48 | S30: =IF($S$1="ASSAULT RATE",SUMIF('Loads + CPFs by TAMCN'!$C$8:$C$1000,'Ammo Pallet Calculator'!A30,'Loads + CPFs by TAMCN'!$L$8:$L$1000),0) -> 334.89 | T30: =IF($S$1="SUSTAIN RATE",SUMIF('Loads + CPFs by TAMCN'!$C$8:$C$1000,'Ammo Pallet Calculator'!A30,'Loads + CPFs by TAMCN'!$M$8:$M$1000),0) -> 0 | U30: =SUM(S30:T30) -> 334.89 | V30: =SUM(U30/C30) -> 1.395375 | W30: =(V30/Q30) -> 0.029070313 | X30: =SUM(V30*H30) -> 79.452652 | Y30: =U30*L30 -> 1.7648703
A31: AX14 | C31: 6000 | D31: 0.01 | E31: 14.44 | F31: 12.53 | G31: 8.12 | H31: 39.14 | I31: =(H31/C31) -> 0.0065233333 | J31: 1.4S | K31: 0044 | L31: 0.000126 | M31: 43.31 | N31: 50.12 | O31: 38 | P31: 2936 | Q31: 48 | S31: =IF($S$1="ASSAULT RATE",SUMIF('Loads + CPFs by TAMCN'!$C$8:$C$1000,'Ammo Pallet Calculator'!A31,'Loads + CPFs by TAMCN'!$L$8:$L$1000),0) -> 0 | T31: =IF($S$1="SUSTAIN RATE",SUMIF('Loads + CPFs by TAMCN'!$C$8:$C$1000,'Ammo Pallet Calculator'!A31,'Loads + CPFs by TAMCN'!$M$8:$M$1000),0) -> 0 | U31: =SUM(S31:T31) -> 0 | V31: =SUM(U31/C31) -> 0 | W31: =(V31/Q31) -> 0 | X31: =SUM(V31*H31) -> 0 | Y31: =U31*L31 -> 0
A32: B504 | C32: 44 | D32: 20.76 | E32: 14.62 | F32: 13.18 | G32: 8.56 | H32: 45.9 | I32: =(H32/C32) -> 1.0431818 | J32: 1.4G | K32: 0312 | L32: 0.18782 | M32: 43.88 | N32: 52.75 | O32: 39.75 | P32: 2296 | Q32: 48 | S32: =IF($S$1="ASSAULT RATE",SUMIF('Loads + CPFs by TAMCN'!$C$8:$C$1000,'Ammo Pallet Calculator'!A32,'Loads + CPFs by TAMCN'!$L$8:$L$1000),0) -> 10.332 | T32: =IF($S$1="SUSTAIN RATE",SUMIF('Loads + CPFs by TAMCN'!$C$8:$C$1000,'Ammo Pallet Calculator'!A32,'Loads + CPFs by TAMCN'!$M$8:$M$1000),0) -> 0 | U32: =SUM(S32:T32) -> 10.332 | V32: =SUM(U32/C32) -> 0.23481818 | W32: =(V32/Q32) -> 0.0048920455 | X32: =SUM(V32*H32) -> 10.778155 | Y32: =U32*L32 -> 1.9405562
A33: B505 | C33: 44 | D33: 20.78 | E33: 14.62 | F33: 13.18 | G33: 8.56 | H33: 45.9 | I33: =(H33/C33) -> 1.0431818 | J33: 1.4G | K33: 0312 | L33: 0.00247 | M33: 43.88 | N33: 52.75 | O33: 39.75 | P33: 2296 | Q33: 48 | S33: =IF($S$1="ASSAULT RATE",SUMIF('Loads + CPFs by TAMCN'!$C$8:$C$1000,'Ammo Pallet Calculator'!A33,'Loads + CPFs by TAMCN'!$L$8:$L$1000),0) -> 10.332 | T33: =IF($S$1="SUSTAIN RATE",SUMIF('Loads + CPFs by TAMCN'!$C$8:$C$1000,'Ammo Pallet Calculator'!A33,'Loads + CPFs by TAMCN'!$M$8:$M$1000),0) -> 0 | U33: =SUM(S33:T33) -> 10.332 | V33: =SUM(U33/C33) -> 0.23481818 | W33: =(V33/Q33) -> 0.0048920455 | X33: =SUM(V33*H33) -> 10.778155 | Y33: =U33*L33 -> 0.02552004
A34: B506 | C34: 44 | D34: 17.9 | E34: 14.62 | F34: 13.18 | G34: 8.56 | H34: 45.9 | I34: =(H34/C34) -> 1.0431818 | J34: 1.4G | K34: 0197 | L34: 0.17215 | M34: 43.88 | N34: 52.75 | O34: 39.75 | P34: 2296 | Q34: 48 | S34: =IF($S$1="ASSAULT RATE",SUMIF('Loads + CPFs by TAMCN'!$C$8:$C$1000,'Ammo Pallet Calculator'!A34,'Loads + CPFs by TAMCN'!$L$8:$L$1000),0) -> 0 | T34: =IF($S$1="SUSTAIN RATE",SUMIF('Loads + CPFs by TAMCN'!$C$8:$C$1000,'Ammo Pallet Calculator'!A34,'Loads + CPFs by TAMCN'!$M$8:$M$1000),0) -> 0 | U34: =SUM(S34:T34) -> 0 | V34: =SUM(U34/C34) -> 0 | W34: =(V34/Q34) -> 0 | X34: =SUM(V34*H34) -> 0 | Y34: =U34*L34 -> 0
A35: B508 | C35: 44 | D35: 17.48 | E35: 14.62 | F35: 13.18 | G35: 8.56 | H35: 45.9 | I35: =(H35/C35) -> 1.0431818 | J35: 1.4G | K35: 0197 | L35: 0.17215 | M35: 43.88 | N35: 52.75 | O35: 39.75 | P35: 2296 | Q35: 48 | S35: =IF($S$1="ASSAULT RATE",SUMIF('Loads + CPFs by TAMCN'!$C$8:$C$1000,'Ammo Pallet Calculator'!A35,'Loads + CPFs by TAMCN'!$L$8:$L$1000),0) -> 10.332 | T35: =IF($S$1="SUSTAIN RATE",SUMIF('Loads + CPFs by TAMCN'!$C$8:$C$1000,'Ammo Pallet Calculator'!A35,'Loads + CPFs by TAMCN'!$M$8:$M$1000),0) -> 0 | U35: =SUM(S35:T35) -> 10.332 | V35: =SUM(U35/C35) -> 0.23481818 | W35: =(V35/Q35) -> 0.0048920455 | X35: =SUM(V35*H35) -> 10.778155 | Y35: =U35*L35 -> 1.7786538
A36: B509 | C36: 44 | D36: 17.93 | E36: 14.62 | F36: 13.18 | G36: 8.56 | H36: 45.9 | I36: =(H36/C36) -> 1.0431818 | J36: 1.4G | K36: 0197 | L36: 0.17215 | M36: 43.88 | N36: 52.75 | O36: 39.75 | P36: 2296 | Q36: 48 | S36: =IF($S$1="ASSAULT RATE",SUMIF('Loads + CPFs by TAMCN'!$C$8:$C$1000,'Ammo Pallet Calculator'!A36,'Loads + CPFs by TAMCN'!$L$8:$L$1000),0) -> 10.332 | T36: =IF($S$1="SUSTAIN RATE",SUMIF('Loads + CPFs by TAMCN'!$C$8:$C$1000,'Ammo Pallet Calculator'!A36,'Loads + CPFs by TAMCN'!$M$8:$M$1000),0) -> 0 | U36: =SUM(S36:T36) -> 10.332 | V36: =SUM(U36/C36) -> 0.23481818 | W36: =(V36/Q36) -> 0.0048920455 | X36: =SUM(V36*H36) -> 10.778155 | Y36: =U36*L36 -> 1.7786538
A37: B535 | C37: 44 | D37: 50.44 | E37: 14.62 | F37: 13.18 | G37: 8.56 | H37: 45.9 | I37: =(H37/C37) -> 1.0431818 | J37: 1.4G | K37: 0312 | L37: 0.208 | M37: 43.88 | N37: 52.75 | O37: 39.75 | P37: 2296 | Q37: 48 | S37: =IF($S$1="ASSAULT RATE",SUMIF('Loads + CPFs by TAMCN'!$C$8:$C$1000,'Ammo Pallet Calculator'!A37,'Loads + CPFs by TAMCN'!$L$8:$L$1000),0) -> 11.07 | T37: =IF($S$1="SUSTAIN RATE",SUMIF('Loads + CPFs by TAMCN'!$C$8:$C$1000,'Ammo Pallet Calculator'!A37,'Loads + CPFs by TAMCN'!$M$8:$M$1000),0) -> 0 | U37: =SUM(S37:T37) -> 11.07 | V37: =SUM(U37/C37) -> 0.25159091 | W37: =(V37/Q37) -> 0.0052414773 | X37: =SUM(V37*H37) -> 11.548023 | Y37: =U37*L37 -> 2.30256
A38: B542 | C38: 32 | D38: 11.41 | E38: 18.75 | F38: 6.38 | G38: 10.38 | H38: 42 | I38: =(H38/C38) -> 1.3125 | J38: 1.1E | K38: 0006 | L38: 0.09414 | M38: 51 | N38: 40 | O38: 36.12 | P38: 2291 | Q38: 48 | S38: =IF($S$1="ASSAULT RATE",SUMIF('Loads + CPFs by TAMCN'!$C$8:$C$1000,'Ammo Pallet Calculator'!A38,'Loads + CPFs by TAMCN'!$L$8:$L$1000),0) -> 12638.088 | T38: =IF($S$1="SUSTAIN RATE",SUMIF('Loads + CPFs by TAMCN'!$C$8:$C$1000,'Ammo Pallet Calculator'!A38,'Loads + CPFs by TAMCN'!$M$8:$M$1000),0) -> 0 | U38: =SUM(S38:T38) -> 12638.088 | V38: =SUM(U38/C38) -> 394.94025 | W38: =(V38/Q38) -> 8.2279219 | X38: =SUM(V38*H38) -> 16587.49 | Y38: =U38*L38 -> 1189.7496
A39: B546 | C39: 72 | D39: 15.44 | E39: 15.88 | F39: 13.88 | G39: 10 | H39: 53 | I39: =(H39/C39) -> 0.73611111 | J39: 1.1E | K39: 0006 | L39: 0.101715 | M39: 40.12 | N39: 48 | O39: 35.5 | P39: 1531 | Q39: 27 | S39: =IF($S$1="ASSAULT RATE",SUMIF('Loads + CPFs by TAMCN'!$C$8:$C$1000,'Ammo Pallet Calculator'!A39,'Loads + CPFs by TAMCN'!$L$8:$L$1000),0) -> 318.078 | T39: =IF($S$1="SUSTAIN RATE",SUMIF('Loads + CPFs by TAMCN'!$C$8:$C$1000,'Ammo Pallet Calculator'!A39,'Loads + CPFs by TAMCN'!$M$8:$M$1000),0) -> 0 | U39: =SUM(S39:T39) -> 318.078 | V39: =SUM(U39/C39) -> 4.41775 | W39: =(V39/Q39) -> 0.16362037 | X39: =SUM(V39*H39) -> 234.14075 | Y39: =U39*L39 -> 32.353304
A40: B567 | C40: 24 | D40: 50.59 | E40: 15.25 | F40: 11.62 | G40: 6.62 | H40: 26 | I40: =(H40/C40) -> 1.0833333 | J40: 1.4C | K40: 0301 | L40: 0.125 | M40: 37.88 | N40: 49 | O40: 45.25 | P40: 1506 | Q40: 54 | S40: =IF($S$1="ASSAULT RATE",SUMIF('Loads + CPFs by TAMCN'!$C$8:$C$1000,'Ammo Pallet Calculator'!A40,'Loads + CPFs by TAMCN'!$L$8:$L$1000),0) -> 8.172 | T40: =IF($S$1="SUSTAIN RATE",SUMIF('Loads + CPFs by TAMCN'!$C$8:$C$1000,'Ammo Pallet Calculator'!A40,'Loads + CPFs by TAMCN'!$M$8:$M$1000),0) -> 0 | U40: =SUM(S40:T40) -> 8.172 | V40: =SUM(U40/C40) -> 0.3405 | W40: =(V40/Q40) -> 0.0063055556 | X40: =SUM(V40*H40) -> 8.853 | Y40: =U40*L40 -> 1.0215
...
